<?xml version="1.0"?>

<robot name="sam_bot" xmlns:xacro="http://ros.org/wiki/xacro">

  <!-- Define robot constants -->
  <xacro:property name="base_width" value="0.44"/>
  <xacro:property name="base_length" value="0.525"/>
  <xacro:property name="base_height" value="0.41"/>

  <xacro:property name="wheel_radius" value="0.09"/>
  <xacro:property name="wheel_width" value="0.04"/>
  <xacro:property name="wheel_ygap" value="0.04"/>
  <xacro:property name="wheel_zoff" value="0.15"/>
  <xacro:property name="wheel_xoff" value="0.3475"/>

  <xacro:property name="caster_xoff" value="0.14"/>

  <!-- Define some commonly used intertial properties  -->
  <xacro:macro name="box_inertia" params="m w h d">
    <inertial>
      <origin xyz="0 0 0" rpy="${pi/2} 0 ${pi/2}"/>      
      <mass value="${m}"/>
      <inertia ixx="${(m/12) * (h*h + d*d)}" ixy="0.0" ixz="0.0" iyy="${(m/12) * (w*w + d*d)}" iyz="0.0" izz="${(m/12) * (w*w + h*h)}"/>
    </inertial>
  </xacro:macro>

  <xacro:macro name="cylinder_inertia" params="m r h">
    <inertial>
      <origin xyz="0 0 0" rpy="${pi/2} 0 0" />      
      <mass value="${m}"/>
      <inertia ixx="${(m/12) * (3*r*r + h*h)}" ixy = "0" ixz = "0" iyy="${(m/12) * (3*r*r + h*h)}" iyz = "0" izz="${(m/2) * (r*r)}"/> 
    </inertial>
  </xacro:macro>

  <xacro:macro name="sphere_inertia" params="m r">
    <inertial>
      <mass value="${m}"/>
      <inertia ixx="${(2/5) * m * (r*r)}" ixy="0.0" ixz="0.0" iyy="${(2/5) * m * (r*r)}" iyz="0.0" izz="${(2/5) * m * (r*r)}"/>
    </inertial>
  </xacro:macro>
  
  <!-- Robot Base -->
  <link name="base_link">
    <visual>
      <geometry>
        <box size="${base_length} ${base_width} ${base_height}"/>
      </geometry>
      <material name="Cyan">
        <color rgba="0 1.0 1.0 1.0"/>
      </material>
    </visual>

    <collision>
      <geometry>
        <box size="${base_length} ${base_width} ${base_height}"/>
      </geometry>
    </collision>

    <xacro:box_inertia m="15" w="${base_width}" d="${base_length}" h="${base_height}"/>
  </link>
<!-- 
  <link name="dummy">
   </link>
  <joint name="dummy_joint" type="fixed">
     <parent link="dummy"/>
     <child link="base_link"/>
   </joint> -->

  
   <!-- Robot Footprint -->
  <link name="base_footprint">
  	<xacro:box_inertia m="0" w="0" d="0" h="0"/>
  </link>

  <joint name="base_joint" type="fixed">
    <parent link="base_link"/>
    <child link="base_footprint"/>
    <origin xyz="0.0 0.0 ${-(wheel_radius+wheel_zoff)}" rpy="0 0 0"/>
  </joint>

  <!-- Wheels -->
  <xacro:macro name="wheel" params="prefix x_reflect y_reflect">
    <link name="${prefix}_link">
      <visual>
        <origin xyz="0 0 0" rpy="${pi/2} 0 0"/>
        <geometry>
            <cylinder radius="${wheel_radius}" length="${wheel_width}"/>
        </geometry>
        <material name="Gray">
          <color rgba="0.5 0.5 0.5 1.0"/>
        </material>
      </visual>

      <collision>
        <origin xyz="0 0 0" rpy="${pi/2} 0 0"/> 
        <geometry>
          <cylinder radius="${wheel_radius}" length="${wheel_width}"/>
        </geometry>
      </collision>

      <xacro:cylinder_inertia m="1.5" r="${wheel_radius}" h="${wheel_width}"/>
    </link>

    <joint name="${prefix}_joint" type="continuous">
      <parent link="base_link"/>
      <child link="${prefix}_link"/>
      <origin xyz="${x_reflect*wheel_xoff} ${y_reflect*(base_width/2-wheel_ygap)} ${-wheel_zoff}" rpy="0 0 0"/>
      <axis xyz="0 1 0"/>
    </joint>
  </xacro:macro>

  <xacro:wheel prefix="drivewhl_l" x_reflect="-1" y_reflect="1" />
  <xacro:wheel prefix="drivewhl_r" x_reflect="-1" y_reflect="-1" />


    <link name="front_caster">
      <visual>
        <geometry>
          <sphere radius="${(wheel_radius+wheel_zoff-(base_height/2))}"/>
        </geometry>
        <material name="Cyan">
          <color rgba="0 1.0 1.0 1.0"/>
        </material>
      </visual>

      <collision>
        <origin xyz="0 0 0" rpy="0 0 0"/>
        <geometry>
          <sphere radius="${(wheel_radius+wheel_zoff-(base_height/2))}"/>
        </geometry>
      </collision>

      <xacro:sphere_inertia m="0.5" r="${(wheel_radius+wheel_zoff-(base_height/2))}"/>
    </link>

    <joint name="caster_joint" type="fixed">
      <parent link="base_link"/>
      <child link="front_caster"/>
      <origin xyz="${caster_xoff} 0.0 ${-(base_height/2)}" rpy="0 0 0"/>
    </joint>


  <!-- Small wheels -->
  <!-- <xacro:macro name="caster" params="prefix y_reflect">
    <link name="${prefix}_link">
      <visual>
        <origin xyz="0 0 0" rpy="${pi/2} 0 0"/>
        <geometry>
            <cylinder radius="0.02" length="${wheel_width}"/>
        </geometry>
        <material name="Gray">
          <color rgba="0.5 0.5 0.5 1.0"/>
        </material>
      </visual>

      <collision>
        <origin xyz="0 0 0" rpy="${pi/2} 0 0"/> 
        <geometry>
          <cylinder radius="0.02" length="${wheel_width}"/>
        </geometry>
      </collision>

      <xacro:cylinder_inertia m="3.5" r="0.02" h="${wheel_width}"/>
    </link>

    <joint name="${prefix}_joint" type="continuous">
      <parent link="base_link"/>
      <child link="${prefix}_link"/>
      <origin xyz="0.25 ${y_reflect*0.18} -0.235" rpy="0 0 0"/>
      <axis xyz="0 1 0"/>
    </joint>
  </xacro:macro>

  <xacro:caster prefix="caster_l" y_reflect="1" />
  <xacro:caster prefix="caster_r" y_reflect="-1" /> -->

  <link name="imu_link">
    <visual>
      <geometry>
        <box size="0.05 0.05 0.05"/>
      </geometry>
    </visual>
    
    <collision>
      <geometry>
        <box size="0.05 0.05 0.05"/>
      </geometry>
    </collision>
      
    <xacro:box_inertia m="0.05" w="0.05" d="0.05" h="0.05"/>
  </link>

   
  <gazebo>
    <plugin name='diff_drive' filename='libgazebo_ros_diff_drive.so'>
      <ros>
        <namespace>/demo</namespace>
      </ros>

      <!-- wheels -->
      <left_joint>drivewhl_l_joint</left_joint>
      <right_joint>drivewhl_r_joint</right_joint>

      <!-- kinematics -->
      <wheel_separation>0.4</wheel_separation>
      <wheel_diameter>0.2</wheel_diameter>

      <!-- limits -->	
      <max_wheel_torque>20</max_wheel_torque>
      <max_wheel_acceleration>1.0</max_wheel_acceleration>

      <!-- output -->
      <publish_odom>true</publish_odom>
      <publish_odom_tf>false</publish_odom_tf>
      <publish_wheel_tf>true</publish_wheel_tf>

      <odometry_frame>odom</odometry_frame>
      <robot_base_frame>base_link</robot_base_frame>
    </plugin>
  </gazebo>
    
  <joint name="imu_joint" type="fixed">
    <parent link="base_link"/>
    <child link="imu_link"/>
    <origin xyz="-0.2175 0 0.23"/>
  </joint>
  
 <link name="lidar_link">
    <inertial>
      <origin xyz="0 0 0" rpy="0 0 0"/>
      <mass value="0.125"/>
      <inertia ixx="0.001"  ixy="0"  ixz="0" iyy="0.001" iyz="0" izz="0.001" />
    </inertial>

    <collision>
      <origin xyz="0 0 0" rpy="0 0 0"/>
      <geometry>
         <cylinder radius="0.06" length="0.09"/>
      </geometry>
    </collision>

    <visual>
      <origin xyz="0 0 0" rpy="0 0 0"/>
      <geometry>
         <cylinder radius="0.06" length="0.09"/>
      </geometry>
    </visual>
  </link>
    
  <joint name="lidar_joint" type="fixed">
    <parent link="base_link"/>
    <child link="lidar_link"/>
    <origin xyz="0.1925 0 0.25" rpy="0 0 0"/>
  </joint>
    
</robot>
